Workbook

Sheet Appetizers
A1: Period: 01/01/2026 – 31/01/2026
A2: Dish Name | B2: Category | C2: Component | D2: Type | E2: Qty | F2: Unit | G2: Unit Price (₪) | H2: Component Total (₪) | I2: Selling Price (₪) | J2: Unit Cost (₪) | K2: COGS % | L2: Qty Sold | M2: Sales Revenue (₪) | N2: Theoretical Food Cost (₪) | O2: COGS % on Sales
A3: carpaccio special | B3: Appetizers | I3: 62 | J3: 16.84144 | K3: 0.32053063 | L3: 111 | M3: =L3*(I3/1.18) -> 5832.2034 | N3: =L3*J3 -> 1869.3998 | O3: =N3/M3 -> 0.32053063
C4: רכז רימונים גלון 4 ק"ג | D4: Item | E4: 0.01 | F4: kg | G4: 22 | H4: 0.22
C5: רימון | D5: Item | E5: 0.05 | F5: kg | G5: 15 | H5: 0.75
C6: גבינת פרמזן איטלקי | D6: Item | E6: 0.05 | F6: kg | G6: 68 | H6: 3.4
C7: פלפל שחור גרוס | D7: Item | E7: 0.001 | F7: kg | G7: 45 | H7: 0.045
C8: מלח שולחן | D8: Item | E8: 0.001 | F8: kg | G8: 1.44 | H8: 0.00144
C9: לחמניית המבורגר עגולה רגילה 100 גרם | D9: Item | E9: 1 | F9: unit | G9: 2.35 | H9: 2.35
C10: רוקט | D10: Item | E10: 0.03 | F10: unit | G10: 2.5 | H10: 0.075
C11: קרפצ׳יו מנה | D11: Item | E11: 1 | F11: unit | G11: 10 | H11: 10
A13: כנפיים קריספי | B13: Appetizers | I13: 35 | J13: 4.52682 | K13: 0.1526185 | L13: 407 | M13: =L13*(I13/1.18) -> 12072.034 | N13: =L13*J13 -> 1842.4157 | O13: =N13/M13 -> 0.1526185
C14: שומשום | D14: Item | E14: 0.003 | F14: kg | G14: 14.44 | H14: 0.04332
C15: ציפוי לכנפיים | D15: Recipe | E15: 0.04 | F15: Kg | G15: 3.49 | H15: 0.1396
C16: כנפיים | D16: Item | E16: 0.35 | F16: kg | G16: 11.5 | H16: 4.025
C17: רוטב צ׳ילי מתוק | D17: Recipe | E17: 0.03 | F17: Kg | G17: 10.63 | H17: 0.3189
A19: קריספי צ׳יקן קטן | B19: Appetizers | I19: 23 | J19: 4.7103 | K19: 0.24165887 | L19: 830 | M19: =L19*(I19/1.18) -> 16177.966 | N19: =L19*J19 -> 3909.549 | O19: =N19/M19 -> 0.24165887
C20: אריזה | D20: Temporary | E20: 1 | F20: units | G20: 0.7 | H20: 0.7
C21: קוביות חזה עוף | D21: Item | E21: 0.12 | F21: kg | G21: 28 | H21: 3.36
C22: פירי פירי | D22: Recipe | E22: 0.02 | F22: Kg | G22: 12.96 | H22: 0.2592
C23: רוטב צ׳ילי מתוק | D23: Recipe | E23: 0.03 | F23: Kg | G23: 10.63 | H23: 0.3189
C24: שומשום | D24: Item | E24: 0.005 | F24: kg | G24: 14.44 | H24: 0.0722
A26: מיני צ׳יזי סטיק | B26: Appetizers | I26: 28 | J26: =SUM(H27:H31) -> 5.9345 | K26: 0.24503964 | L26: 493 | M26: =L26*(I26/1.18) -> 11698.305 | N26: =L26*J26 -> 2925.7085 | O26: =N26/M26 -> 0.25009679
C27: אריזה | D27: Temporary | E27: 1 | F27: units | G27: 0.7 | H27: 0.7
C28: אורז תפוח | D28: Item | E28: 0.02 | F28: kg | G28: 16.5 | H28: =G28*E28 -> 0.33
C29: מוצרלה אצבעות | D29: Item | E29: 0.1 | F29: kg | G29: 40 | H29: 4
C30: איולי צ׳יפוטלה | D30: Recipe | E30: 0.03 | F30: Kg | G30: 12.87 | H30: 0.3861
C31: פירי פירי | D31: Recipe | E31: 0.04 | F31: Kg | G31: 12.96 | H31: 0.5184
A33: קריספי צ׳יקן | B33: Appetizers | I33: 33 | J33: 8.3295 | K33: 0.29784273 | L33: 1040 | M33: =L33*(I33/1.18) -> 29084.746 | N33: =L33*J33 -> 8662.68 | O33: =N33/M33 -> 0.29784273
C34: אריזה | D34: Temporary | E34: 1 | F34: units | G34: 0.7 | H34: 0.7
C35: קוביות חזה עוף | D35: Item | E35: 0.24 | F35: kg | G35: 28 | H35: 6.72
C36: פירי פירי | D36: Recipe | E36: 0.04 | F36: Kg | G36: 12.96 | H36: 0.5184
C37: רוטב צ׳ילי מתוק | D37: Recipe | E37: 0.03 | F37: Kg | G37: 10.63 | H37: 0.3189
C38: שומשום | D38: Item | E38: 0.005 | F38: kg | G38: 14.44 | H38: 0.0722
A40: פוריטו רביולי | B40: Appetizers | I40: 48 | J40: 13.8758 | K40: 0.34111342 | L40: 325 | M40: =L40*(I40/1.18) -> 13220.339 | N40: =L40*J40 -> 4509.635 | O40: =N40/M40 -> 0.34111342
C41: אריזה | D41: Temporary | E41: 1 | F41: units | G41: 0.7 | H41: 0.7
C42: בזיליקום | D42: Item | E42: 0.01 | F42: kg | G42: 30 | H42: 0.33
C43: גבינת פרמזן איטלקי | D43: Item | E43: 0.02 | F43: kg | G43: 68 | H43: 1.36
C44: שמנת פלפלת | D44: Recipe | E44: 0.03 | F44: Kg | G44: 28.9 | H44: 0.867
C45: שמנת פטריות | D45: Recipe | E45: 0.03 | F45: Kg | G45: 30.22 | H45: 0.9066
...

Sheet beside the burger
A1: Period: 01/01/2026 – 31/01/2026
A2: Dish Name | B2: Category | C2: Component | D2: Type | E2: Qty | F2: Unit | G2: Unit Price (₪) | H2: Component Total (₪) | I2: Selling Price (₪) | J2: Unit Cost (₪) | K2: COGS % | L2: Qty Sold | M2: Sales Revenue (₪) | N2: Theoretical Food Cost (₪) | O2: COGS % on Sales
A3: בטטה קריספי | B3: beside the burger | I3: 26 | J3: 4.27 | K3: 0.19379231 | L3: 76 | M3: =L3*(I3/1.18) -> 1674.5763 | N3: =L3*J3 -> 324.52 | O3: =N3/M3 -> 0.19379231
C4: אריזה | D4: Temporary | E4: 1 | F4: units | G4: 0.7 | H4: 0.7
C5: גולד צ׳יפס בטטה קריספי 1 ק״ג/10 | D5: Item | E5: 0.17 | F5: kg | G5: 21 | H5: 3.57
A7: הום פרייז x | B7: beside the burger | I7: 22 | J7: 6.601 | K7: 0.35405364 | L7: 117 | M7: =L7*(I7/1.18) -> 2181.3559 | N7: =L7*J7 -> 772.317 | O7: =N7/M7 -> 0.35405364
C8: גולד צ׳יפס בטטה קריספי 1 ק״ג/10 | D8: Item | E8: 0.12 | F8: kg | G8: 21 | H8: 2.52
C9: אריזה | D9: Temporary | E9: 1 | F9: units | G9: 0.7 | H9: 0.7
C10: פוטטוס צ׳יפס מובחר 2.5ק״ג/4 | D10: Item | E10: 0.1 | F10: kg | G10: 10.2 | H10: 1.02
C11: חמאת שום קונפי | D11: Recipe | E11: 0.06 | F11: Kg | G11: 39.35 | H11: 2.361
A13: לחמניה | B13: beside the burger | I13: 7 | J13: 2.35 | K13: 0.39614286 | L13: 112 | M13: =L13*(I13/1.18) -> 664.40678 | N13: =L13*J13 -> 263.2 | O13: =N13/M13 -> 0.39614286
C14: לחמניית המבורגר עגולה רגילה 100 גרם | D14: Item | E14: 1 | F14: unit | G14: 2.35 | H14: 2.35
A16: לחמניה ללא גלוטן | B16: beside the burger | I16: 7 | J16: 4.15 | K16: 0.69957143 | L16: 47 | M16: =L16*(I16/1.18) -> 278.81356 | N16: =L16*J16 -> 195.05 | O16: =N16/M16 -> 0.69957143
C17: לחמניות ללא גלוטן (מכירה) | D17: Item | E17: 1 | F17: unit | G17: 4.15 | H17: 4.15
A19: מיקס מטוגן | B19: beside the burger | I19: 24 | J19: =SUM(H20:H25) -> 6.38405 | K19: =J19/(I19/1.18) -> 0.31388246 | L19: 634 | M19: =L19*(I19/1.18) -> 12894.915 | N19: =L19*J19 -> 4047.4877 | O19: =N19/M19 -> 0.31388246
C20: אריזה | D20: Temporary | E20: 1 | F20: units | G20: 0.7 | H20: 0.7
C21: פוטטוס צ׳יפס מובחר 2.5ק״ג/4 | D21: Item | E21: 0.06 | F21: kg | G21: 10.2 | H21: 0.612
C22: 10*10 קריספי פלוס (פרימיום) 2.5/4 | D22: Item | E22: 0.17 | F22: kg | G22: 13.16 | H22: 2.2372
C23: טבעות בצל | D23: Item | E23: 0.09 | F23: kg | G23: =H23/E23*1 -> 17.777778 | H23: 1.6
C24: כדורי פירה | D24: Item | E24: 0.06 | F24: kg | G24: 18.8 | H24: 1.128
C25: תבלין פילדלפיה | D25: Item | E25: 0.005 | F25: kg | G25: 21.37 | H25: 0.10685
A27: פוטטו חמאת צ׳ילי הדרים | B27: beside the burger | I27: 22 | J27: 3.5399 | K27: 0.18986736 | L27: 67 | M27: =L27*(I27/1.18) -> 1249.1525 | N27: =L27*J27 -> 237.1733 | O27: =N27/M27 -> 0.18986736
C28: אריזה | D28: Temporary | E28: 1 | F28: units | G28: 0.7 | H28: 0.7
C29: רוטב צ׳ילי מתוק | D29: Recipe | E29: 0.03 | F29: Kg | G29: 10.63 | H29: 0.3189
C30: פוטטוס צ׳יפס מובחר 2.5ק״ג/4 | D30: Item | E30: 0.17 | F30: kg | G30: 10.2 | H30: 1.734
C31: חמאת שום קונפי | D31: Recipe | E31: 0.02 | F31: Kg | G31: 39.35 | H31: 0.787
A33: צ׳יפס המפנק | B33: beside the burger | I33: 28 | J33: 7.2404 | K33: 0.30513114 | L33: 296 | M33: =L33*(I33/1.18) -> 7023.7288 | N33: =L33*J33 -> 2143.1584 | O33: =N33/M33 -> 0.30513114
C34: אריזה | D34: Temporary | E34: 1 | F34: units | G34: 0.7 | H34: 0.7
C35: 10*10 קריספי פלוס (פרימיום) 2.5/4 | D35: Item | E35: 0.34 | F35: kg | G35: 13.16 | H35: 4.4744
C36: שמנת פלפלת | D36: Recipe | E36: 0.04 | F36: Kg | G36: 28.9 | H36: 1.156
C37: פטרוזיליה קצוצה | D37: Item | E37: 0.01 | F37: kg | G37: 23 | H37: 0.23
C38: גבינת פרמזן איטלקי | D38: Item | E38: 0.01 | F38: kg | G38: 68 | H38: 0.68
A40: צ'יפס פילדלפיה קטן | B40: beside the burger | I40: 14 | J40: 2.34405 | K40: 0.19756993 | L40: 914 | M40: =L40*(I40/1.18) -> 10844.068 | N40: =L40*J40 -> 2142.4617 | O40: =N40/M40 -> 0.19756993
C41: תבלין פילדלפיה | D41: Item | E41: 0.005 | F41: kg | G41: 21.37 | H41: 0.10685
C42: 10*10 קריספי פלוס (פרימיום) 2.5/4 | D42: Item | E42: 0.17 | F42: kg | G42: 13.16 | H42: 2.2372
A44: צ'יפס פילדלפיה גדול | B44: beside the burger | I44: 24 | J44: 5.697 | K44: 0.2801025 | L44: 548 | M44: =L44*(I44/1.18) -> 11145.763 | N44: =L44*J44 -> 3121.956 | O44: =N44/M44 -> 0.2801025
C45: אריזה | D45: Temporary | E45: 1 | F45: units | G45: 0.7 | H45: 0.7
C46: שמן חמניות 5 ליטר | D46: Item | E46: 0.05 | F46: L | G46: 6.178 | H46: 0.3089
C47: תבלין פילדלפיה | D47: Item | E47: 0.01 | F47: kg | G47: 21.37 | H47: 0.2137
C48: 10*10 קריספי פלוס (פרימיום) 2.5/4 | D48: Item | E48: 0.34 | F48: kg | G48: 13.16 | H48: 4.4744
...

Sheet Beverages
A1: Period: 01/01/2026 – 31/01/2026
A2: Dish Name | B2: Category | C2: Component | D2: Type | E2: Qty | F2: Unit | G2: Unit Price (₪) | H2: Component Total (₪) | I2: Selling Price (₪) | J2: Unit Cost (₪) | K2: COGS % | L2: Qty Sold | M2: Sales Revenue (₪) | N2: Theoretical Food Cost (₪) | O2: COGS % on Sales
A3: 7 up | B3: Beverages | I3: 9 | J3: 2.3308333 | K3: 0.30559815 | L3: 5 | M3: 19.01 | N3: 11.654167 | O3: 0.72340435
C4: סבן אפ פחית צרה 330 שישייה ח | D4: Item | E4: 1 | F4: unit | G4: 2.3308333 | H4: 2.3308333
A6: 7 up פחית | B6: Beverages | I6: 9 | J6: 2.3308333 | K6: 0.30559815 | L6: 160 | M6: 1344.17 | N6: 372.93333 | O6: 0.32738518
C7: סבן אפ פחית צרה 330 שישייה ח | D7: Item | E7: 1 | F7: unit | G7: 2.3308333 | H7: 2.3308333
A9: sprite zero | B9: Beverages | I9: 9 | J9: 2.5516458 | K9: 0.33454912 | L9: 57 | M9: 490.84 | N9: 145.44381 | O9: 0.34965304
C10: סליק ספרייט LIME מבצע | D10: Item | E10: 1 | F10: unit | G10: 2.5516458 | H10: 2.5516458
A12: אקסל | B12: Beverages | I12: 8 | J12: 2.5816667 | K12: 0.38079583 | L12: 131 | M12: 889.68 | N12: 338.19833 | O12: 0.44855907
C13: XL פחית | D13: Item | E13: 1 | F13: unit | G13: 2.5816667 | H13: 2.5816667
A15: ג'ינג'ר אייל | B15: Beverages | I15: 12 | J15: 3.5219542 | K15: 0.34632549 | L15: 44 | M15: 495 | N15: 154.96598 | O15: 0.36941386
C16: ג'ינג'ר אייל בקבוק | D16: Item | E16: 1 | F16: unit | G16: 3.5219542 | H16: 3.5219542
A18: מי טוניק | B18: Beverages | I18: 12 | J18: 3.5220833 | K18: 0.34633819 | L18: 3 | M18: 33 | N18: 10.56625 | O18: 0.37782348
C19: מי טוניק בקבוק | D19: Item | E19: 1 | F19: unit | G19: 3.5220833 | H19: 3.5220833
A21: מים מינרלים | B21: Beverages | I21: 6 | J21: 1.5267292 | K21: 0.30025674 | L21: 279 | M21: 1631.14 | N21: 425.95744 | O21: 0.30814631
C22: סן בנדטו 500 מ"ל 4 שישיות | D22: Item | E22: 1 | F22: unit | G22: 1.5267292 | H22: 1.5267292
A24: מיץ ענבים | B24: Beverages | I24: 8 | J24: 2.4025 | K24: 0.35436875 | L24: 155 | M24: 1185.75 | N24: 372.3875 | O24: 0.3705817
C25: ג'אמפ אקסטרה פרוט ענבים 330 בק' 24 יח | D25: Item | E25: 1 | F25: unit | G25: 2.4025 | H25: 2.4025
A27: מיץ תות | B27: Beverages | I27: 8 | J27: 2.4029167 | K27: 0.35443021 | L27: 72 | M27: 554.37 | N27: 173.01 | O27: 0.3682591
C28: ג'אמפ אקסטרה פרוט תות בננה 330 בק' 24 יח | D28: Item | E28: 1 | F28: unit | G28: 2.4029167 | H28: 2.4029167
A30: מיץ תפוזים | B30: Beverages | I30: 8 | J30: 2.4025 | K30: 0.35436875 | L30: 36 | M30: 268.29 | N30: 86.49 | O30: 0.38040255
C31: ג'אמפ אקסטרה פרוט תפוזים 330 בק' 24 יח | D31: Item | E31: 1 | F31: unit | G31: 2.4025 | H31: 2.4025
A33: מירנדה פחית | B33: Beverages | I33: 9 | J33: 2.33125 | K33: 0.30565278 | L33: 85 | M33: 730.35 | N33: 198.15625 | O33: 0.32015386
C34: מירינדה פחית צרה 330 שישייה ח | D34: Item | E34: 1 | F34: unit | G34: 2.33125 | H34: 2.33125
A36: נסטי | B36: Beverages | I36: 10 | J36: 4.3508333 | K36: 0.51339833 | L36: 68 | M36: 661 | N36: 295.85667 | O36: 0.52815562
C37: שרינק FUZE tea אפרסק - 0.5 ליטר | D37: Item | E37: 1 | F37: unit | G37: 4.3508333 | H37: 4.3508333
A39: סודה | B39: Beverages | I39: 8 | J39: 1.8795833 | K39: 0.27723854 | L39: 93 | M39: 673.56 | N39: 174.80125 | O39: 0.30623178
C40: סודה 275 מ"ל בקבוק 24 יח' | D40: Item | E40: 1 | F40: unit | G40: 1.8795833 | H40: 1.8795833
A42: פפסי מקס פחית | B42: Beverages | I42: 9 | J42: 3.7120833 | K42: 0.48669537 | L42: 38 | M42: 255.81 | N42: 141.05917 | O42: 0.65067752
C43: פפסי מקס פחית צרה 330 שישייה ח | D43: Item | E43: 1 | F43: unit | G43: 3.7120833 | H43: 3.7120833
A45: פפסי פחית | B45: Beverages | I45: 9 | J45: 2.075 | K45: 0.27205556 | L45: 38 | M45: 234.19 | N45: 78.85 | O45: 0.39729707
C46: פפסי 330 פחית צרה שישייה ח | D46: Item | E46: 1 | F46: unit | G46: 2.075 | H46: 2.075
A48: קולה זירו פחית | B48: Beverages | I48: 9 | J48: 2.5516458 | K48: 0.33454912 | L48: 989 | M48: 8729.23 | N48: 2523.5777 | O48: 0.34113223
C49: סליק קולה 330 ZERO מ מבע | D49: Item | E49: 1 | F49: unit | G49: 2.5516458 | H49: 2.5516458
A51: קולה פחית | B51: Beverages | I51: 9 | J51: 2.55 | K51: 0.33433333 | L51: 1249 | M51: 11021.5 | N51: 3184.95 | O51: 0.34099179
C52: קולה פחית | D52: Item | E52: 1 | F52: unit | G52: 2.55 | H52: 2.55

Sheet children
A1: Period: 01/01/2026 – 31/01/2026
A2: Dish Name | B2: Category | C2: Component | D2: Type | E2: Qty | F2: Unit | G2: Unit Price (₪) | H2: Component Total (₪) | I2: Selling Price (₪) | J2: Unit Cost (₪) | K2: COGS % | L2: Qty Sold | M2: Sales Revenue (₪) | N2: Theoretical Food Cost (₪) | O2: COGS % on Sales
A3: בורגר ילדים | B3: children | I3: 35 | J3: 10.1142 | K3: 0.34099303 | L3: 682 | M3: =L3*(I3/1.18) -> 20228.814 | N3: =L3*J3 -> 6897.8844 | O3: =N3/M3 -> 0.34099303
C4: אריזה | D4: Temporary | E4: 1 | F4: units | G4: 0.7 | H4: 0.7
C5: בשר מתובל להמבורגר | D5: Recipe | E5: 0.11 | F5: Kg | G5: 38 | H5: 4.18
C6: רוטב איולי חרדל | D6: Recipe | E6: 0.02 | F6: Kg | G6: 12.05 | H6: 0.241
C7: מלפפון חמוץ | D7: Recipe | E7: 0.02 | F7: Kg | G7: 8.3 | H7: 0.166
C8: חסה אייסברג להמבורגר | D8: Item | E8: 0.02 | F8: kg | G8: 9.5 | H8: 0.19
C9: עגבניה | D9: Item | E9: 0.04 | F9: kg | G9: 10 | H9: 0.4
C10: 10*10 קריספי פלוס (פרימיום) 2.5/4 | D10: Item | E10: 0.17 | F10: kg | G10: 13.16 | H10: 2.2372
C11: המבורגר עגולה ילדים 85 גרם | D11: Item | E11: 1 | F11: unit | G11: 2 | H11: 2
A13: שניצל ילדים | B13: children | I13: 35 | J13: 9.5827 | K13: 0.32307389 | L13: 105 | M13: =L13*(I13/1.18) -> 3114.4068 | N13: =L13*J13 -> 1006.1835 | O13: =N13/M13 -> 0.32307389
C14: חזה עוף פרוס | D14: Item | E14: 0.12 | F14: kg | G14: 28 | H14: 3.36
C15: רוטב איולי חרדל | D15: Recipe | E15: 0.03 | F15: Kg | G15: 12.05 | H15: 0.3615
C16: מלפפון חמוץ | D16: Recipe | E16: 0.03 | F16: Kg | G16: 8.3 | H16: 0.249
C17: חסה אייסברג להמבורגר | D17: Item | E17: 0.03 | F17: kg | G17: 9.5 | H17: 0.285
C18: עגבניה | D18: Item | E18: 0.03 | F18: kg | G18: 10 | H18: 0.3
C19: 10*10 קריספי פלוס (פרימיום) 2.5/4 | D19: Item | E19: 0.17 | F19: kg | G19: 13.16 | H19: 2.2372
C20: מרינדה לשניצל | D20: Recipe | E20: 0.05 | F20: Kg | G20: 14.06 | H20: 0.703
C21: פרורי לחם כתומים | D21: Item | E21: 0.015 | F21: kg | G21: 5.8 | H21: 0.087
C22: המבורגר עגולה ילדים 85 גרם | D22: Item | E22: 1 | F22: unit | G22: 2 | H22: 2

Sheet enlarge burger
A1: Period: 01/01/2026 – 31/01/2026
A2: Dish Name | B2: Category | C2: Component | D2: Type | E2: Qty | F2: Unit | G2: Unit Price (₪) | H2: Component Total (₪) | I2: Selling Price (₪) | J2: Unit Cost (₪) | K2: COGS % | L2: Qty Sold | M2: Sales Revenue (₪) | N2: Theoretical Food Cost (₪) | O2: COGS % on Sales
A3: הגדלה 150 גרם | B3: enlarge burger | I3: 10 | J3: 1.52 | K3: 0.17936 | L3: 37 | M3: =L3*(I3/1.18) -> 313.55932 | N3: =L3*J3 -> 56.24 | O3: =N3/M3 -> 0.17936
C4: בשר מתובל להמבורגר | D4: Recipe | E4: 0.04 | F4: Kg | G4: 38 | H4: 1.52
A6: הגדלה ל 220 גרם | B6: enlarge burger | I6: 15 | J6: 2.66 | K6: 0.20925333 | L6: 123 | M6: =L6*(I6/1.18) -> 1563.5593 | N6: =L6*J6 -> 327.18 | O6: =N6/M6 -> 0.20925333
C7: בשר מתובל להמבורגר | D7: Recipe | E7: 0.07 | F7: Kg | G7: 38 | H7: 2.66
A9: הגדלה ל 300 גרם | B9: enlarge burger | I9: 20 | J9: 5.7 | K9: 0.3363 | L9: 253 | M9: =L9*(I9/1.18) -> 4288.1356 | N9: =L9*J9 -> 1442.1 | O9: =N9/M9 -> 0.3363
C10: בשר מתובל להמבורגר | D10: Recipe | E10: 0.15 | F10: Kg | G10: 38 | H10: 5.7
A12: הגדלה ל 450 גרם | B12: enlarge burger | I12: 30 | J12: 11.4 | K12: 0.4484 | L12: 46 | M12: =L12*(I12/1.18) -> 1169.4915 | N12: =L12*J12 -> 524.4 | O12: =N12/M12 -> 0.4484
C13: בשר מתובל להמבורגר | D13: Recipe | E13: 0.3 | F13: Kg | G13: 38 | H13: 11.4

Sheet family
A1: Period: 01/01/2026 – 31/01/2026
A2: Dish Name | B2: Category | C2: Component | D2: Type | E2: Qty | F2: Unit | G2: Unit Price (₪) | H2: Component Total (₪) | I2: Selling Price (₪) | J2: Unit Cost (₪) | K2: COGS % | L2: Qty Sold | M2: Sales Revenue (₪) | N2: Theoretical Food Cost (₪) | O2: COGS % on Sales
A3: Crispy package small | B3: family | I3: 190 | J3: =SUM(H4:H18) -> 47.05308 | K3: =J3/(I3/1.18) -> 0.29222439 | L3: 68 | M3: =L3*(I3/1.18) -> 10949.153 | N3: =L3*J3 -> 3199.6094 | O3: =N3/M3 -> 0.29222439
C4: מארז צ׳יפס | D4: Item | E4: 4 | F4: unit | G4: 0.59 | H4: 2.36
C5: בוקס בורגר משפחתי 50 יח קריספי | D5: Item | E5: 1 | F5: unit | G5: 4.64 | H5: 4.64
C6: שומשום | D6: Item | E6: 0.001 | F6: kg | G6: 14.44 | H6: 0.01444
C7: רוטב צ׳ילי מתוק | D7: Recipe | E7: 0.03 | F7: Kg | G7: 10.63 | H7: 0.3189
C8: קוביות חזה עוף | D8: Item | E8: 0.12 | F8: kg | G8: 28 | H8: 3.36
C9: פירי פירי | D9: Recipe | E9: 0.02 | F9: Kg | G9: 12.96 | H9: 0.2592
C10: טבעות בצל | D10: Item | E10: 0.09 | F10: kg | G10: 8.136 | H10: 0.73224
C11: כדורי פירה | D11: Item | E11: 0.09 | F11: kg | G11: 18.8 | H11: 1.692
C12: עגבניה | D12: Item | E12: 0.12 | F12: kg | G12: 10 | H12: 1.2
C13: מלפפון חמוץ | D13: Recipe | E13: 0.06 | F13: Kg | G13: 8.3 | H13: 0.498
C14: רוטב איולי חרדל | D14: Recipe | E14: 0.09 | F14: Kg | G14: 12.05 | H14: 1.0845
C15: בשר מתובל להמבורגר | D15: Recipe | E15: 0.45 | F15: Kg | G15: 40.46 | H15: =G15*E15 -> 18.207
C16: לחמניית המבורגר עגולה רגילה 100 גרם | D16: Item | E16: 3 | F16: unit | G16: 2.35 | H16: 7.05
C17: 10*10 קריספי פלוס (פרימיום) 2.5/4 | D17: Item | E17: 0.23 | F17: kg | G17: 13.16 | H17: 3.0268
C18: גבינת גאודה | D18: Item | E18: 0.09 | F18: kg | G18: 29 | H18: 2.61

Sheet hamburgers
A1: Period: 01/01/2026 – 31/01/2026
A2: Dish Name | B2: Category | C2: Component | D2: Type | E2: Qty | F2: Unit | G2: Unit Price (₪) | H2: Component Total (₪) | I2: Selling Price (₪) | J2: Unit Cost (₪) | K2: COGS % | L2: Qty Sold | M2: Sales Revenue (₪) | N2: Theoretical Food Cost (₪) | O2: COGS % on Sales
A3: 220 קלאסי בורגר | B3: hamburgers | I3: 47 | J3: =SUM(H4:H11) -> 13.4087 | K3: =J3/(I3/1.18) -> 0.33664396 | L3: 1116 | M3: =L3*(I3/1.18) -> 44450.847 | N3: =L3*J3 -> 14964.109 | O3: =N3/M3 -> 0.33664396
C4: לחמניית המבורגר עגולה רגילה 100 גרם | D4: Item | E4: 1 | F4: unit | G4: 2.35 | H4: 2.35
C5: רוטב איולי חרדל | D5: Recipe | E5: 0.03 | F5: Kg | G5: 12.05 | H5: 0.3615
C6: חסה להמבורגרים | D6: Item | E6: 0.03 | F6: kg | G6: 14 | H6: =G6*E6 -> 0.42
C7: עגבניה | D7: Item | E7: 0.04 | F7: kg | G7: 10 | H7: 0.4
C8: בצל מקולף | D8: Item | E8: 0.02 | F8: kg | G8: 5.5 | H8: 0.11
C9: מלפפון חמוץ | D9: Recipe | E9: 0.02 | F9: Kg | G9: 8.3 | H9: 0.166
C10: בשר מתובל להמבורגר | D10: Recipe | E10: 0.22 | F10: Kg | G10: 40.46 | H10: =G10*E10 -> 8.9012
C11: אריזה | D11: Temporary | E11: 1 | F11: units | G11: 0.7 | H11: 0.7
A13: קלאסיק בורגר 150 | B13: hamburgers | I13: 39 | J13: =SUM(H14:H21) -> 10.5195 | K13: =J13/(I13/1.18) -> 0.31828231 | L13: 2206 | M13: =L13*(I13/1.18) -> 72910.169 | N13: =L13*J13 -> 23206.017 | O13: =N13/M13 -> 0.31828231
C14: לחמניית המבורגר עגולה רגילה 100 גרם | D14: Item | E14: 1 | F14: unit | G14: 2.35 | H14: 2.35
C15: רוטב איולי חרדל | D15: Recipe | E15: 0.03 | F15: Kg | G15: 12.05 | H15: 0.3615
C16: חסה להמבורגרים | D16: Item | E16: 0.02 | F16: kg | G16: 14 | H16: =G16*E16 -> 0.28
C17: עגבניה | D17: Item | E17: 0.04 | F17: kg | G17: 10 | H17: 0.4
C18: בצל מקולף | D18: Item | E18: 0.02 | F18: kg | G18: 5.5 | H18: 0.11
C19: מלפפון חמוץ | D19: Recipe | E19: 0.03 | F19: Kg | G19: 8.3 | H19: 0.249
C20: בשר מתובל להמבורגר | D20: Recipe | E20: 0.15 | F20: Kg | G20: 40.46 | H20: =G20*E20 -> 6.069
C21: אריזה | D21: Temporary | E21: 1 | F21: units | G21: 0.7 | H21: 0.7
A23: קלאסי בורגר 110 | B23: hamburgers | I23: 35 | J23: =SUM(H24:H31) -> 8.3476 | K23: =J23/(I23/1.18) -> 0.28143337 | L23: 474 | M23: =L23*(I23/1.18) -> 14059.322 | N23: =L23*J23 -> 3956.7624 | O23: =N23/M23 -> 0.28143337
C24: המבורגר עגולה ילדים 85 גרם | D24: Item | E24: 1 | F24: unit | G24: 2 | H24: 2
C25: רוטב איולי חרדל | D25: Recipe | E25: 0.02 | F25: Kg | G25: 12.05 | H25: 0.241
C26: חסה להמבורגרים | D26: Item | E26: 0.02 | F26: kg | G26: 14 | H26: =G26*E26 -> 0.28
C27: עגבניה | D27: Item | E27: 0.04 | F27: kg | G27: 10 | H27: 0.4
C28: בצל מקולף | D28: Item | E28: 0.02 | F28: kg | G28: 5.5 | H28: 0.11
C29: מלפפון חמוץ | D29: Recipe | E29: 0.02 | F29: Kg | G29: 8.3 | H29: 0.166
C30: בשר מתובל להמבורגר | D30: Recipe | E30: 0.11 | F30: Kg | G30: 40.46 | H30: =G30*E30 -> 4.4506
C31: אריזה | D31: Temporary | E31: 1 | F31: units | G31: 0.7 | H31: 0.7
A33: קלאסי בורגר 300 | B33: hamburgers | I33: 57 | J33: =SUM(H34:H41) -> 16.6455 | K33: =J33/(I33/1.18) -> 0.34459105 | L33: 267 | M33: =L33*(I33/1.18) -> 12897.458 | N33: =L33*J33 -> 4444.3485 | O33: =N33/M33 -> 0.34459105
C34: לחמניית המבורגר עגולה רגילה 100 גרם | D34: Item | E34: 1 | F34: unit | G34: 2.35 | H34: 2.35
C35: רוטב איולי חרדל | D35: Recipe | E35: 0.03 | F35: Kg | G35: 12.05 | H35: 0.3615
C36: חסה להמבורגרים | D36: Item | E36: 0.03 | F36: kg | G36: 14 | H36: =G36*E36 -> 0.42
C37: עגבניה | D37: Item | E37: 0.04 | F37: kg | G37: 10 | H37: 0.4
C38: בצל מקולף | D38: Item | E38: 0.02 | F38: kg | G38: 5.5 | H38: 0.11
C39: מלפפון חמוץ | D39: Recipe | E39: 0.02 | F39: Kg | G39: 8.3 | H39: 0.166
C40: בשר מתובל להמבורגר | D40: Recipe | E40: 0.3 | F40: Kg | G40: 40.46 | H40: =G40*E40 -> 12.138
C41: אריזה | D41: Temporary | E41: 1 | F41: units | G41: 0.7 | H41: 0.7
A43: קלאסי 450 | B43: hamburgers | I43: 79 | J43: =SUM(H44:H51) -> 22.7145 | K43: =J43/(I43/1.18) -> 0.33927987 | L43: 32 | M43: =L43*(I43/1.18) -> 2142.3729 | N43: =L43*J43 -> 726.864 | O43: =N43/M43 -> 0.33927987
C44: לחמניית המבורגר עגולה רגילה 100 גרם | D44: Item | E44: 1 | F44: unit | G44: 2.35 | H44: 2.35
...

Sheet long box
A1: Period: 01/01/2026 – 31/01/2026
A2: Dish Name | B2: Category | C2: Component | D2: Type | E2: Qty | F2: Unit | G2: Unit Price (₪) | H2: Component Total (₪) | I2: Selling Price (₪) | J2: Unit Cost (₪) | K2: COGS % | L2: Qty Sold | M2: Sales Revenue (₪) | N2: Theoretical Food Cost (₪) | O2: COGS % on Sales
A3: Long box סלט גבינה (חצי) | B3: long box | I3: 40 | J3: 15.1587 | K3: 0.44718165 | L3: 5 | M3: 160 | N3: 75.7935 | O3: 0.55897706
C4: מארז קרטון שני מקום עם חלון CRICPY&THE X | D4: Item | E4: 0.5 | F4: unit | G4: 5.8 | H4: 2.9
C5: מלפפון | D5: Item | E5: 0.075 | F5: kg | G5: 5 | H5: 0.4125
C6: תערובת חסה לסלט | D6: Recipe | E6: 0.36 | F6: Kg | G6: 13.02 | H6: 4.6872
C7: ויניגרט נענע | D7: Recipe | E7: 0.15 | F7: Kg | G7: 6.43 | H7: 0.9645
C8: זיתי קלמטה מגולענים | D8: Item | E8: 0.03 | F8: kg | G8: 23 | H8: 0.69
C9: עגבניות שרי | D9: Item | E9: 0.06 | F9: kg | G9: 18.9 | H9: 1.134
C10: בצל מקולף | D10: Item | E10: 0.015 | F10: kg | G10: 5.5 | H10: 0.0825
C11: גבינת פטה | D11: Item | E11: 0.16 | F11: kg | G11: 26.8 | H11: 4.288
A13: Long box סלט קינואה (חצי) | B13: long box | I13: 45 | J13: 13.559423 | K13: 0.35555821
C14: מארז קרטון שני מקום עם חלון CRICPY&THE X | D14: Item | E14: 0.5 | F14: unit | G14: 5.8 | H14: 2.9
C15: קינואה בורגול | D15: Recipe | E15: 0.9 | F15: Kg | G15: 10.61 | H15: 9.549
C16: חמוציות | D16: Item | E16: 0.015 | F16: kg | G16: 22.028219 | H16: 0.33042328
C17: שקד מולבן פרוס 10 ק"ג - ח | D17: Item | E17: 0.015 | F17: kg | G17: 52 | H17: 0.78

Sheet on a plate
A1: Period: 01/01/2026 – 31/01/2026
A2: Dish Name | B2: Category | C2: Component | D2: Type | E2: Qty | F2: Unit | G2: Unit Price (₪) | H2: Component Total (₪) | I2: Selling Price (₪) | J2: Unit Cost (₪) | K2: COGS % | L2: Qty Sold | M2: Sales Revenue (₪) | N2: Theoretical Food Cost (₪) | O2: COGS % on Sales
A3: אסאדו פירה | B3: on a plate | I3: 80 | J3: =SUM(H4:H8) -> 11.9097 | K3: =J3/(I3/1.18) -> 0.17566808 | L3: 10 | M3: =L3*(I3/1.18) -> 677.9661 | N3: =L3*J3 -> 119.097 | O3: =N3/M3 -> 0.17566808
C4: שמנת פלפלת | D4: Recipe | E4: 0.05 | F4: Kg | G4: 28.9 | H4: 1.445
C5: שום קונפי | D5: Recipe | E5: 0.03 | F5: Kg | G5: 16.52 | H5: 0.4956
C6: צ׳ימיצ׳ורי | D6: Recipe | E6: 0.03 | F6: Kg | G6: 13.24 | H6: 0.3972
C7: פירה | D7: Recipe | E7: 0.13 | F7: Kg | G7: 19.02 | H7: 2.4726
C8: בשר לאסאדו | D8: Recipe | E8: 0.13 | F8: Kg | G8: 54.61 | H8: =G8*E8 -> 7.0993
A10: חזה עוף בצלחת | B10: on a plate | I10: 46 | J10: 9.3544 | K10: 0.2399607 | L10: 256 | M10: =L10*(I10/1.18) -> 9979.661 | N10: =L10*J10 -> 2394.7264 | O10: =N10/M10 -> 0.2399607
C11: חזה עוף פרוס | D11: Item | E11: 0.24 | F11: kg | G11: 28 | H11: 6.72
C12: צ׳ימיצ׳ורי | D12: Recipe | E12: 0.03 | F12: Kg | G12: 13.24 | H12: 0.3972
C13: 10*10 קריספי פלוס (פרימיום) 2.5/4 | D13: Item | E13: 0.17 | F13: kg | G13: 13.16 | H13: 2.2372
A15: מרגיז פירה | B15: on a plate | I15: 46 | J15: 13.2872 | K15: 0.34084557 | L15: 114 | M15: =L15*(I15/1.18) -> 4444.0678 | N15: =L15*J15 -> 1514.7408 | O15: =N15/M15 -> 0.34084557
C16: מטבוחה | D16: Recipe | E16: 0.02 | F16: Kg | G16: 19.15 | H16: 0.383
C17: בצל מטוגן | D17: Recipe | E17: 0.02 | F17: Kg | G17: 8.6 | H17: 0.172
C18: שום קונפי | D18: Recipe | E18: 0.01 | F18: Kg | G18: 16.52 | H18: 0.1652
C19: צ׳ימיצ׳ורי | D19: Recipe | E19: 0.01 | F19: Kg | G19: 13.24 | H19: 0.1324
C20: שמנת פלפלת | D20: Recipe | E20: 0.06 | F20: Kg | G20: 28.9 | H20: 1.734
C21: מרגז | D21: Item | E21: 0.15 | F21: kg | G21: 47 | H21: 7.05
C22: פטריות מטוגנות | D22: Recipe | E22: 0.02 | F22: Kg | G22: 30.37 | H22: 0.6074
C23: פירה | D23: Recipe | E23: 0.16 | F23: Kg | G23: 19.02 | H23: 3.0432
A25: קריספי קראנץ בצלחת | B25: on a plate | I25: 46 | J25: 9.6348 | K25: 0.24715357 | L25: 159 | M25: =L25*(I25/1.18) -> 6198.3051 | N25: =L25*J25 -> 1531.9332 | O25: =N25/M25 -> 0.24715357
C26: ציפוי לקריספי | D26: Recipe | E26: 0.04 | F26: Kg | G26: 7.01 | H26: 0.2804
C27: חזה עוף פרוס | D27: Item | E27: 0.24 | F27: kg | G27: 28 | H27: 6.72
C28: צ׳ימיצ׳ורי | D28: Recipe | E28: 0.03 | F28: Kg | G28: 13.24 | H28: 0.3972
C29: 10*10 קריספי פלוס (פרימיום) 2.5/4 | D29: Item | E29: 0.17 | F29: kg | G29: 13.16 | H29: 2.2372

Sheet on top of
A1: Period: 01/01/2026 – 31/01/2026
A2: Dish Name | B2: Category | C2: Component | D2: Type | E2: Qty | F2: Unit | G2: Unit Price (₪) | H2: Component Total (₪) | I2: Selling Price (₪) | J2: Unit Cost (₪) | K2: COGS % | L2: Qty Sold | M2: Sales Revenue (₪) | N2: Theoretical Food Cost (₪) | O2: COGS % on Sales
A3: תוספת אסאדו | B3: on top of | I3: 20 | J3: 9.8 | K3: 0.5782 | L3: 49 | M3: =L3*(I3/1.18) -> 830.50847 | N3: =L3*J3 -> 480.2 | O3: =N3/M3 -> 0.5782
C4: אסאדו | D4: Item | E4: 0.1 | F4: kg | G4: 98 | H4: 9.8
A6: אקסטרה עוף | B6: on top of | I6: 15 | J6: 2.5988 | K6: 0.20443893 | L6: =24+7 -> 31 | M6: =L6*(I6/1.18) -> 394.0678 | N6: =L6*J6 -> 80.5628 | O6: =N6/M6 -> 0.20443893
C7: מרינדה לצ׳יקן | D7: Recipe | E7: 0.02 | F7: Kg | G7: 17.94 | H7: 0.3588
C8: חזה עוף פרוס | D8: Item | E8: 0.08 | F8: kg | G8: 28 | H8: 2.24
A10: אקסטרה פטה | B10: on top of | I10: 10 | J10: 1.34 | K10: 0.15812 | L10: 31 | M10: =L10*(I10/1.18) -> 262.71186 | N10: =L10*J10 -> 41.54 | O10: =N10/M10 -> 0.15812
C11: גבינת פטה | D11: Item | E11: 0.05 | F11: kg | G11: 26.8 | H11: 1.34
A13: תוספת ריבת שרי | B13: on top of | I13: 8 | J13: 0.5922 | K13: 0.0873495 | L13: 8 | M13: =L13*(I13/1.18) -> 54.237288 | N13: =L13*J13 -> 4.7376 | O13: =N13/M13 -> 0.0873495
C14: ריבת שרי | D14: Recipe | E14: 0.03 | F14: Kg | G14: 19.74 | H14: 0.5922
A16: בצל מטוגן | B16: on top of | I16: 8 | J16: 0.43 | K16: 0.063425 | L16: 113 | M16: =L16*(I16/1.18) -> 766.10169 | N16: =L16*J16 -> 48.59 | O16: =N16/M16 -> 0.063425
C17: בצל מטוגן | D17: Recipe | E17: 0.05 | F17: Kg | G17: 8.6 | H17: 0.43
A19: תוספת ריבת בצל | B19: on top of | I19: 8 | J19: 0.2505 | K19: 0.03694875 | L19: =21+255 -> 276 | M19: =L19*(I19/1.18) -> 1871.1864 | N19: =L19*J19 -> 69.138 | O19: =N19/M19 -> 0.03694875
C20: ריבת בצל | D20: Recipe | E20: 0.03 | F20: Kg | G20: 8.35 | H20: 0.2505
A22: שום קונפי | B22: on top of | I22: 7 | J22: 0.4956 | K22: 0.083544 | L22: 22 | M22: =L22*(I22/1.18) -> 130.50847 | N22: =L22*J22 -> 10.9032 | O22: =N22/M22 -> 0.083544
C23: שום קונפי | D23: Recipe | E23: 0.03 | F23: Kg | G23: 16.52 | H23: 0.4956
A25: ת.אנטרקוט | B25: on top of | I25: 15 | J25: 2.5 | K25: 0.19666667 | L25: 15 | M25: =L25*(I25/1.18) -> 190.67797 | N25: =L25*J25 -> 37.5 | O25: =N25/M25 -> 0.19666667
C26: אנטרקוט | D26: Item | E26: 0.05 | F26: kg | G26: 50 | H26: 2.5
A28: תוספת אננס | B28: on top of | I28: 7 | J28: 0.694 | K28: 0.11698857 | L28: 25 | M28: =L28*(I28/1.18) -> 148.30508 | N28: =L28*J28 -> 17.35 | O28: =N28/M28 -> 0.11698857
C29: אננס בסירופ | D29: Item | E29: 0.1 | F29: unit | G29: 6.94 | H29: 0.694
A31: ת.ביצת עין | B31: on top of | I31: 8 | J31: 0.95 | K31: 0.140125 | L31: 20 | M31: =L31*(I31/1.18) -> 135.59322 | N31: =L31*J31 -> 19 | O31: =N31/M31 -> 0.140125
C32: ביצים M - מארז 30 יח' | D32: Item | E32: 1 | F32: unit | G32: 0.95 | H32: 0.95
A34: ת.גבינת גאודה | B34: on top of | I34: 8 | J34: 0.87 | K34: 0.128325 | L34: 350 | M34: =L34*(I34/1.18) -> 2372.8814 | N34: =L34*J34 -> 304.5 | O34: =N34/M34 -> 0.128325
C35: גבינת גאודה | D35: Item | E35: 0.03 | F35: kg | G35: 29 | H35: 0.87
A37: ת.גבינת צ׳דר | B37: on top of | I37: 8 | J37: 1.35 | K37: 0.199125 | L37: 1912 | M37: =L37*(I37/1.18) -> 12962.712 | N37: =L37*J37 -> 2581.2 | O37: =N37/M37 -> 0.199125
C38: גבינת צ׳דר | D38: Item | E38: 0.03 | F38: kg | G38: 45 | H38: 1.35
A40: ת.גוואקמולי | B40: on top of | I40: 7 | J40: 1.303964 | K40: 0.21981107 | L40: 74 | M40: =L40*(I40/1.18) -> 438.98305 | N40: =L40*J40 -> 96.493336 | O40: =N40/M40 -> 0.21981107
C41: אבוקדו טבעי 1 ק״ג קפוא | D41: Item | E41: 0.05 | F41: kg | G41: 26.07928 | H41: 1.303964

Sheet Salads
A1: Period: 01/01/2026 – 31/01/2026
A2: Dish Name | B2: Category | C2: Component | D2: Type | E2: Qty | F2: Unit | G2: Unit Price (₪) | H2: Component Total (₪) | I2: Selling Price (₪) | J2: Unit Cost (₪) | K2: COGS % | L2: Qty Sold | M2: Sales Revenue (₪) | N2: Theoretical Food Cost (₪) | O2: COGS % on Sales
A3: סלט קינואה בורגול קטן | B3: Salads | I3: 27 | J3: 5.6842822 | K3: 0.24842418 | L3: 873 | M3: =L3*(I3/1.18) -> 19975.424 | N3: =L3*J3 -> 4962.3783 | O3: =N3/M3 -> 0.24842418
C4: שקד מולבן | D4: Item | E4: 0.01 | F4: kg | G4: 52 | H4: 0.52
C5: קינואה בורגול | D5: Recipe | E5: 0.4 | F5: Kg | G5: 10.61 | H5: 4.244
C6: חמוציות | D6: Item | E6: 0.01 | F6: kg | G6: 22.028219 | H6: 0.22028219
C7: אריזה | D7: Temporary | E7: 1 | F7: units | G7: 0.7 | H7: 0.7
A9: סלט קריספי קטן | B9: Salads | I9: 32 | J9: =SUM(H10:H19) -> 6.5224 | K9: =J9/(I9/1.18) -> 0.2405135 | L9: 163 | M9: =L9*(I9/1.18) -> 4420.339 | N9: =L9*J9 -> 1063.1512 | O9: =N9/M9 -> 0.2405135
C10: תערובת חסה לסלט | D10: Recipe | E10: 0.12 | F10: Kg | G10: 15.74 | H10: =G10*E10 -> 1.8888
C11: ויניגרט נענע | D11: Recipe | E11: 0.03 | F11: Kg | G11: 6.43 | H11: 0.1929
C12: עגבניות שרי | D12: Item | E12: 0.04 | F12: kg | G12: 18.9 | H12: 0.756
C13: בצל מקולף | D13: Item | E13: 0.01 | F13: kg | G13: 5.5 | H13: 0.055
C14: חזה עוף פרוס | D14: Item | E14: 0.08 | F14: kg | G14: 28 | H14: 2.24
C15: זיתי קלמטה מגולענים | D15: Item | E15: 0.01 | F15: kg | G15: 23 | H15: 0.23
C16: רוטב צ׳ילי מתוק | D16: Recipe | E16: 0.01 | F16: Kg | G16: 10.63 | H16: 0.1063
C17: שומשום | D17: Item | E17: 0.005 | F17: kg | G17: 14.44 | H17: 0.0722
C18: אריזה | D18: Temporary | E18: 1 | F18: units | G18: 0.7 | H18: 0.7
C19: מרינדה לשניצל | D19: Recipe | E19: 0.02 | F19: Kg | G19: 14.06 | H19: 0.2812
A21: סלט זהרתנה | B21: Salads | I21: 42 | J21: 6.8352822 | K21: 0.19203888 | L21: 205 | M21: =L21*(I21/1.18) -> 7296.6102 | N21: =L21*J21 -> 1401.2328 | O21: =N21/M21 -> 0.19203888
C22: גבינת פרמזן איטלקי | D22: Item | E22: 0.02 | F22: kg | G22: 68 | H22: 1.36
C23: שקד מולבן | D23: Item | E23: 0.01 | F23: kg | G23: 52 | H23: 0.52
C24: זיתי קלמטה מגולענים | D24: Item | E24: 0.03 | F24: kg | G24: 23 | H24: 0.69
C25: אריזה | D25: Temporary | E25: 1 | F25: units | G25: 0.7 | H25: 0.7
C26: כרובית | D26: Item | E26: 0.17 | F26: unit | G26: 6 | H26: 1.224
C27: רוטב יוגורט טחינה | D27: Recipe | E27: 0.07 | F27: Kg | G27: 11.46 | H27: 0.8022
C28: עגבניה | D28: Item | E28: 0.08 | F28: kg | G28: 10 | H28: 0.8
C29: רוקט | D29: Item | E29: 0.03 | F29: unit | G29: 2.5 | H29: 0.075
C30: בצל מקולף | D30: Item | E30: 0.01 | F30: kg | G30: 5.5 | H30: 0.055
C31: חמוציות | D31: Item | E31: 0.01 | F31: kg | G31: 22.028219 | H31: 0.22028219
C32: ויניגרט רימונים | D32: Recipe | E32: 0.03 | F32: Kg | G32: 12.96 | H32: 0.3888
A34: סלט חלומי גדול | B34: Salads | I34: 48 | J34: =SUM(H35:H42) -> 12.9125 | K34: =J34/(I34/1.18) -> 0.31743229 | L34: 340 | M34: =L34*(I34/1.18) -> 13830.508 | N34: =L34*J34 -> 4390.25 | O34: =N34/M34 -> 0.31743229
C35: אריזה | D35: Temporary | E35: 1 | F35: units | G35: 0.7 | H35: 0.7
C36: עגבניות שרי | D36: Item | E36: 0.04 | F36: kg | G36: 18.9 | H36: 0.756
C37: זיתי קלמטה מגולענים | D37: Item | E37: 0.02 | F37: kg | G37: 23 | H37: 0.46
C38: בצל מקולף | D38: Item | E38: 0.01 | F38: kg | G38: 5.5 | H38: 0.055
C39: תערובת חסה לסלט | D39: Recipe | E39: 0.24 | F39: Kg | G39: 15.74 | H39: =G39*E39 -> 3.7776
C40: רוטב צ׳ילי טריאקי | D40: Recipe | E40: 0.01 | F40: Kg | G40: 16.09 | H40: 0.1609
C41: ויניגרט נענע | D41: Recipe | E41: 0.1 | F41: Kg | G41: 6.43 | H41: 0.643
C42: גבינת חלומי | D42: Item | E42: 0.12 | F42: kg | G42: 53 | H42: 6.36
A44: סלט חלומי קטן | B44: Salads | I44: 32 | J44: =SUM(H45:H52) -> 7.6742 | K44: =J44/(I44/1.18) -> 0.28298612 | L44: 571 | M44: =L44*(I44/1.18) -> 15484.746 | N44: =L44*J44 -> 4381.9682 | O44: =N44/M44 -> 0.28298612
...

Sheet special burger
A1: Period: 01/01/2026 – 31/01/2026
A2: Dish Name | B2: Category | C2: Component | D2: Type | E2: Qty | F2: Unit | G2: Unit Price (₪) | H2: Component Total (₪) | I2: Selling Price (₪) | J2: Unit Cost (₪) | K2: COGS % | L2: Qty Sold | M2: Sales Revenue (₪) | N2: Theoretical Food Cost (₪) | O2: COGS % on Sales
A3: the x 220 | B3: special burger | I3: 69 | J3: =SUM(H4:H12) -> 23.0141 | K3: =J3/(I3/1.18) -> 0.39357446 | L3: 1785 | M3: =L3*(I3/1.18) -> 104377.12 | N3: =L3*J3 -> 41080.168 | O3: =N3/M3 -> 0.39357446
C4: לחמניית המבורגר עגולה רגילה 100 גרם | D4: Item | E4: 1 | F4: unit | G4: 2.35 | H4: 2.35
C5: רוטב איולי חרדל | D5: Recipe | E5: 0.03 | F5: Kg | G5: 12.05 | H5: 0.3615
C6: בשר מתובל להמבורגר | D6: Recipe | E6: 0.22 | F6: Kg | G6: 40.46 | H6: =G6*E6 -> 8.9012
C7: גבינת צ׳דר | D7: Item | E7: 0.03 | F7: kg | G7: 45 | H7: 1.35
C8: שמנת פטריות | D8: Recipe | E8: 0.1 | F8: Kg | G8: 30.22 | H8: 3.022
C9: אנטרקוט | D9: Item | E9: 0.07 | F9: kg | G9: 50 | H9: 3.5
C10: ריבת שרי | D10: Recipe | E10: 0.03 | F10: Kg | G10: 19.74 | H10: 0.5922
C11: 10*10 קריספי פלוס (פרימיום) 2.5/4 | D11: Item | E11: 0.17 | F11: kg | G11: 13.16 | H11: 2.2372
C12: אריזה | D12: Temporary | E12: 1 | F12: units | G12: 0.7 | H12: 0.7
A14: smash בורגר | B14: special burger | I14: 49 | J14: =SUM(H15:H21) -> 10.5029 | K14: =J14/(I14/1.18) -> 0.25292698 | L14: 373 | M14: =L14*(I14/1.18) -> 15488.983 | N14: =L14*J14 -> 3917.5817 | O14: =N14/M14 -> 0.25292698
C15: אריזה | D15: Temporary | E15: 1 | F15: units | G15: 0.7 | H15: 0.7
C16: צהובה גאודה פרוס (שקיל) | D16: Item | E16: 0.03 | F16: kg | G16: 29 | H16: 0.87
C17: מלפפון חמוץ | D17: Recipe | E17: 0.02 | F17: Kg | G17: 8.3 | H17: 0.166
C18: בשר מתובל להמבורגר | D18: Recipe | E18: 0.16 | F18: Kg | G18: 40.46 | H18: =G18*E18 -> 6.4736
C19: רוטב טרטר | D19: Recipe | E19: 0.02 | F19: Kg | G19: 8.64 | H19: 0.1728
C20: רוטב איולי חרדל | D20: Recipe | E20: 0.01 | F20: Kg | G20: 12.05 | H20: 0.1205
C21: המבורגר עגולה ילדים 85 גרם | D21: Item | E21: 1 | F21: unit | G21: 2 | H21: 2
A23: the lobs-burger | B23: special burger | I23: 69 | J23: =SUM(H24:H31) -> 13.149589 | K23: =J23/(I23/1.18) -> 0.22487702 | L23: 95 | M23: =L23*(I23/1.18) -> 5555.0847 | N23: =L23*J23 -> 1249.2109 | O23: =N23/M23 -> 0.22487702
C24: אריזה | D24: Temporary | E24: 1 | F24: units | G24: 0.7 | H24: 0.7
C25: פוטטוס צ׳יפס מובחר 2.5ק״ג/4 | D25: Item | E25: 0.17 | F25: kg | G25: 10.2 | H25: 1.734
C26: ברבקיו | D26: Item | E26: 0.03 | F26: kg | G26: 13.859649 | H26: 0.41578947
C27: וולפאק קטשופ | D27: Item | E27: 0.03 | F27: kg | G27: 9.6599691 | H27: 0.28979907
C28: גבינת צ׳דר | D28: Item | E28: 0.03 | F28: kg | G28: 45 | H28: 1.35
C29: בשר מתובל להמבורגר | D29: Recipe | E29: 0.15 | F29: Kg | G29: 40.46 | H29: =G29*E29 -> 6.069
C30: רוטב איולי חרדל | D30: Recipe | E30: 0.02 | F30: Kg | G30: 12.05 | H30: 0.241
C31: לחמניית המבורגר עגולה רגילה 100 גרם | D31: Item | E31: 1 | F31: unit | G31: 2.35 | H31: 2.35
A33: the x | B33: special burger | I33: 59 | J33: =SUM(H34:H42) -> 20.1819 | K33: =J33/(I33/1.18) -> 0.403638 | L33: 934 | M33: =L33*(I33/1.18) -> 46700 | N33: =L33*J33 -> 18849.895 | O33: =N33/M33 -> 0.403638
C34: לחמניית המבורגר עגולה רגילה 100 גרם | D34: Item | E34: 1 | F34: unit | G34: 2.35 | H34: 2.35
C35: רוטב איולי חרדל | D35: Recipe | E35: 0.03 | F35: Kg | G35: 12.05 | H35: 0.3615
C36: בשר מתובל להמבורגר | D36: Recipe | E36: 0.15 | F36: Kg | G36: 40.46 | H36: =G36*E36 -> 6.069
C37: גבינת צ׳דר | D37: Item | E37: 0.03 | F37: kg | G37: 45 | H37: 1.35
C38: שמנת פטריות | D38: Recipe | E38: 0.1 | F38: Kg | G38: 30.22 | H38: 3.022
C39: אנטרקוט | D39: Item | E39: 0.07 | F39: kg | G39: 50 | H39: 3.5
C40: ריבת שרי | D40: Recipe | E40: 0.03 | F40: Kg | G40: 19.74 | H40: 0.5922
C41: 10*10 קריספי פלוס (פרימיום) 2.5/4 | D41: Item | E41: 0.17 | F41: kg | G41: 13.16 | H41: 2.2372
C42: אריזה | D42: Temporary | E42: 1 | F42: units | G42: 0.7 | H42: 0.7
A44: אסאדו בורגר | B44: special burger | I44: 69 | J44: =SUM(H45:H53) -> 20.1939 | K44: =J44/(I44/1.18) -> 0.34534496 | L44: 196 | M44: =L44*(I44/1.18) -> 11461.017 | N44: =L44*J44 -> 3958.0044 | O44: =N44/M44 -> 0.34534496
...

Sheet wraps
A1: Period: 01/01/2026 – 31/01/2026
A2: Dish Name | B2: Category | C2: Component | D2: Type | E2: Qty | F2: Unit | G2: Unit Price (₪) | H2: Component Total (₪) | I2: Selling Price (₪) | J2: Unit Cost (₪) | K2: COGS % | L2: Qty Sold | M2: Sales Revenue (₪) | N2: Theoretical Food Cost (₪) | O2: COGS % on Sales
A3: אלקבבג׳י רול | B3: wraps | I3: 45 | J3: =SUM(H4:H10) -> 11.5899 | K3: =J3/(I3/1.18) -> 0.30391293 | L3: 96 | M3: =L3*(I3/1.18) -> 3661.0169 | N3: =L3*J3 -> 1112.6304 | O3: =N3/M3 -> 0.30391293
C4: 10*10 קריספי פלוס (פרימיום) 2.5/4 | D4: Item | E4: 0.05 | F4: kg | G4: 13.16 | H4: 0.658
C5: אריזה | D5: Temporary | E5: 1 | F5: units | G5: 0.7 | H5: 0.7
C6: רוטב טרטר | D6: Recipe | E6: 0.05 | F6: Kg | G6: 8.64 | H6: 0.432
C7: מלפפון חמוץ | D7: Recipe | E7: 0.02 | F7: Kg | G7: 8.3 | H7: 0.166
C8: איולי צ׳יפוטלה | D8: Recipe | E8: 0.02 | F8: Kg | G8: 12.87 | H8: 0.2574
C9: בשר מתובל להמבורגר | D9: Recipe | E9: 0.15 | F9: Kg | G9: 40.61 | H9: =G9*E9 -> 6.0915
C10: טורטיה 30 ס"מ טבעי | D10: Item | E10: 1 | F10: unit | G10: 3.285 | H10: 3.285
A12: רול מקסיקאני | B12: wraps | I12: 45 | J12: =SUM(H13:H19) -> 15.548578 | K12: =J12/(I12/1.18) -> 0.40771828 | L12: 374 | M12: =L12*(I12/1.18) -> 14262.712 | N12: =L12*J12 -> 5815.1683 | O12: =N12/M12 -> 0.40771828
C13: אריזה | D13: Temporary | E13: 1 | F13: units | G13: 0.7 | H13: 0.7
C14: בשר לרול מקסיקני | D14: Recipe | E14: 0.18 | F14: Kg | G14: 51.9 | H14: =G14*E14 -> 9.342
C15: אבוקדו טבעי 1 ק״ג קפוא | D15: Item | E15: 0.03 | F15: kg | G15: 26.07928 | H15: 0.7823784
C16: צ׳ימיצ׳ורי | D16: Recipe | E16: 0.03 | F16: Kg | G16: 13.24 | H16: 0.3972
C17: גבינת גאודה | D17: Item | E17: 0.03 | F17: kg | G17: 29 | H17: 0.87
C18: בצל מטוגן | D18: Recipe | E18: 0.02 | F18: Kg | G18: 8.6 | H18: 0.172
C19: טורטיה 30 ס"מ טבעי | D19: Item | E19: 1 | F19: unit | G19: 3.285 | H19: 3.285
A21: רול עוף | B21: wraps | I21: 35 | J21: =SUM(H22:H28) -> 10.0868 | K21: =J21/(I21/1.18) -> 0.34006926 | L21: 355 | M21: =L21*(I21/1.18) -> 10529.661 | N21: =L21*J21 -> 3580.814 | O21: =N21/M21 -> 0.34006926
C22: מרינדה לצ׳יקן | D22: Recipe | E22: 0.05 | F22: Kg | G22: 17.94 | H22: 0.897
C23: רוטב טרטר | D23: Recipe | E23: 0.07 | F23: Kg | G23: 8.64 | H23: 0.6048
C24: אריזה | D24: Temporary | E24: 1 | F24: units | G24: 0.7 | H24: 0.7
C25: חזה עוף פרוס | D25: Item | E25: 0.14 | F25: kg | G25: 28 | H25: 3.92
C26: חסה אייסברג להמבורגר | D26: Item | E26: 0.02 | F26: kg | G26: 14 | H26: =G26*E26 -> 0.28
C27: עגבניה | D27: Item | E27: 0.04 | F27: kg | G27: 10 | H27: 0.4
C28: טורטיה 30 ס"מ טבעי | D28: Item | E28: 1 | F28: unit | G28: 3.285 | H28: 3.285
A30: רול קריספי | B30: wraps | I30: 35 | J30: =SUM(H31:H38) -> 9.417 | K30: =J30/(I30/1.18) -> 0.31748743 | L30: 67 | M30: =L30*(I30/1.18) -> 1987.2881 | N30: =L30*J30 -> 630.939 | O30: =N30/M30 -> 0.31748743
C31: ציפוי לקריספי | D31: Recipe | E31: 0.02 | F31: Kg | G31: 7.01 | H31: 0.1402
C32: רוטב טרטר | D32: Recipe | E32: 0.07 | F32: Kg | G32: 8.64 | H32: 0.6048
C33: אריזה | D33: Temporary | E33: 1 | F33: units | G33: 0.7 | H33: 0.7
C34: חזה עוף פרוס | D34: Item | E34: 0.14 | F34: kg | G34: 28 | H34: 3.92
C35: חסה אייסברג להמבורגר | D35: Item | E35: 0.02 | F35: kg | G35: 14 | H35: =G35*E35 -> 0.28
C36: עגבניה | D36: Item | E36: 0.04 | F36: kg | G36: 10 | H36: 0.4
C37: טורטיה 30 ס"מ טבעי | D37: Item | E37: 1 | F37: unit | G37: 3.285 | H37: 3.285
C38: פרורי לחם כתומים | D38: Item | E38: 0.015 | F38: kg | G38: 5.8 | H38: 0.087
A40: רול שניצל | B40: wraps | I40: 35 | J40: =SUM(H41:H48) -> 9.558 | K40: =J40/(I40/1.18) -> 0.32224114 | L40: 279 | M40: =L40*(I40/1.18) -> 8275.4237 | N40: =L40*J40 -> 2666.682 | O40: =N40/M40 -> 0.32224114
C41: רוטב טרטר | D41: Recipe | E41: 0.07 | F41: Kg | G41: 8.64 | H41: 0.6048
C42: אריזה | D42: Temporary | E42: 1 | F42: units | G42: 0.7 | H42: 0.7
C43: חזה עוף פרוס | D43: Item | E43: 0.14 | F43: kg | G43: 28 | H43: 3.92
C44: חסה אייסברג להמבורגר | D44: Item | E44: 0.02 | F44: kg | G44: 14 | H44: =G44*E44 -> 0.28
...

Sheet 📊 Summary
A1: Dishes Cost & Sales Summary
A2: Period: 01/01/2026 – 31/01/2026
A4: Category | B4: Qty Sold | C4: % of Total Sales | D4: Sales Revenue (₪) | E4: Theoretical Food Cost (₪) | F4: COGS % on Sales
A5: Appetizers | B5: =SUM(Appetizers!L3:L100) -> 4477 | C5: =D5/$D$17 -> 0.15656326 | D5: =SUM(Appetizers!M3:M116) -> 131484.75 | E5: =SUM(Appetizers!N3:N114) -> 36330.774 | F5: =E5/D5 -> 0.2763117
A6: beside the burger | B6: =SUM('beside the burger'!L3:L118) -> 3471 | C6: =D6/$D$17 -> 0.061765757 | D6: =SUM('beside the burger'!M3:M132) -> 51872.034 | E6: =SUM('beside the burger'!N3:N78) -> 15185.876 | F6: =E6/D6 -> 0.29275652
A7: children | B7: =SUM(children!L3:L28) -> 787 | C7: =D7/$D$17 -> 0.027795549 | D7: =SUM(children!M3:M28) -> 23343.22 | E7: =SUM(children!N3:N34) -> 7904.0679 | F7: =E7/D7 -> 0.33860229
A8: enlarge burger | B8: =SUM('enlarge burger'!L3:L231) -> 459 | C8: =D8/$D$17 -> 0.0087337258 | D8: =SUM('enlarge burger'!M3:M51) -> 7334.7458 | E8: =SUM('enlarge burger'!N3:N30) -> 2349.92 | F8: =E8/D8 -> 0.32038193
A9: family | B9: =family!L3 -> 68 | C9: =D9/$D$17 -> 0.01303752 | D9: =family!M3 -> 10949.153 | E9: =family!N3 -> 3199.6094 | F9: =E9/D9 -> 0.29222439
A10: hamburgers | B10: =SUM(hamburgers!L3:L58) -> 4097 | C10: =D10/$D$17 -> 0.17447976 | D10: =SUM(hamburgers!M3:M165) -> 146531.36 | E10: =SUM(hamburgers!N3:N80) -> 47311.347 | F10: =E10/D10 -> 0.32287524
A11: on a plate | B11: =SUM('on a plate'!L3:L250) -> 539 | C11: =D11/$D$17 -> 0.025362619 | D11: =SUM('on a plate'!M3:M84) -> 21300 | E11: =SUM('on a plate'!N3:N33) -> 5560.4974 | F11: =E11/D11 -> 0.26105622
A12: on top of | B12: =SUM('on top of'!L3:L64) -> 2926 | C12: =D12/$D$17 -> 0.02447966 | D12: =SUM('on top of'!M3:M55) -> 20558.475 | E12: =SUM('on top of'!N3:N42) -> 3791.7149 | F12: =E12/D12 -> 0.18443562
A13: Salads | B13: =SUM(Salads!L3:L124) -> 3976 | C13: =D13/$D$17 -> 0.13485155 | D13: =SUM(Salads!M3:M124) -> 113250.85 | E13: =SUM(Salads!N3:N149) -> 30127.29 | F13: =E13/D13 -> 0.26602265
A14: special burger | B14: =SUM('special burger'!L3:L205) -> 5510 | C14: =D14/$D$17 -> 0.32683005 | D14: =SUM('special burger'!M3:M243) -> 274477.97 | E14: =SUM('special burger'!N3:N284) -> 96946.124 | F14: =E14/D14 -> 0.35320185
A15: wraps | B15: =SUM(wraps!L3:L66) -> 1171 | C15: =D15/$D$17 -> 0.04610055 | D15: =SUM(wraps!M3:M83) -> 38716.102 | E15: =SUM(wraps!N3:N72) -> 13806.234 | F15: =E15/D15 -> 0.35660186
A17: TOTAL | B17: 18584 | C17: 1 | D17: =SUM(D5:D15) -> 839818.64 | E17: =SUM(E5:E15) -> 262513.46 | F17: =E17/D17 -> 0.3125835
